src/output.txt
28800758 S 8832.56
28800796 S NA
28800812 S 8832.56
28800974 B 8865.0
28800975 B NA
28812071 S NA
28813830 B 8845.0
28814087 B 8836.0
28815937 B 8845.0
28816245 B 8840.0
28817570 B 8829.2
28822172 B 8830.0
28823984 S 8807.0
28823984 S NA
28835564 S 8757.0
28835565 S NA
28838797 B 8828.5
28845097 B 8820.0
28855165 S 8776.0
28855165 S NA
28869845 S 8783.0
28874354 S NA
28874384 S 8770.0
28876376 S NA
28876679 S 8770.0
28887878 S NA
28890455 S 8746.0
28890455 S NA
28893420 B 8814.0
28893682 S 8759.0
28900102 B 8820.0
28900102 S 8808.0
28902467 S 8776.0
28902514 B 8815.0
28902534 S NA
28902571 S 8765.0
28903189 S 8778.0
28903190 B 8810.0
28903191 S 8765.0
28903191 B 8815.0
28903215 S 8778.0
28903217 B 8810.0
28903874 B 8815.0
28904189 S 8771.0
28904189 B 8820.0
28904224 S NA
28904253 S 8765.0
28906024 S 8771.0
28910721 B 8815.14
28910722 B 8820.0
28910723 B 8815.14
28910744 B 8810.14
28911618 B 8810.71
28912943 B 8818.0
28912944 B 8805.849999999999
28917479 B 8806.6
28917481 S 8779.0
28917481 B 8803.68
28917483 S 8771.0
28917483 B 8806.6
28917524 S 8772.0
28917525 S NA
28917531 S 8779.0
28917539 B 8803.68
28918102 S 8785.0
28918103 B 8806.6
28918132 B 8803.68
28918662 S 8778.0
28918687 S 8784.0
28919172 B 8809.0
28919173 S 8778.0
28919173 B 8818.0
28919173 B 8806.6
28919248 S 8783.0
28919260 B 8802.68
28919822 B 8808.0
28919823 B 8802.68
28922492 S 8778.0
28922492 B 8806.6
28923035 B 8818.0
28923083 B 8827.0
28923113 B 8824.0
28923389 S 8782.2
28923389 B 8816.71
28923390 S 8778.0
28923390 B 8824.0
28923391 S 8782.2
28923391 B 8816.71
28923830 S 8785.6
28923831 S 8782.2
28923832 S 8785.6
28924704 S 8785.0
28924704 B 8824.0
28924704 S 8778.0
28924705 B 8816.71
28924706 S 8782.2
28924706 S 8785.6
28925782 B 8824.0
28925782 S 8782.2
28925782 S 8778.0
28925783 B 8816.71
28925784 S 8782.2
28925784 S 8785.6
28927133 B 8824.0
28927133 S 8785.0
28927134 B 8816.71
28927135 S 8785.6
28928212 S 8785.0
28928212 B 8824.0
28928213 S 8785.6
28928213 B 8816.71
28929118 B 8821.21
28929120 S 8786.0
28929120 B 8812.83
28929121 S 8785.6
28929121 B 8815.0
28929121 S 8782.2
28929121 B 8824.0
28929122 S 8778.0
28929122 S 8785.0
28929123 B 8821.52
28929123 S 8785.6
28929128 B 8813.14
28929146 S 8786.0
28929164 B 8814.52
28929214 B 8813.14
28929949 B 8821.52
28929949 S 8785.6
28929980 S 8785.0
28929981 B 8824.0
28929984 B 8827.0
28930015 B 8824.0
28933055 S 8788.0
28933058 S 8789.0
28933092 S 8788.0
28933093 S 8789.0
28937566 B 8819.5
28937567 S 8788.0
28937568 S 8791.0
28937974 S 8788.0
28937976 S 8791.0
28938015 S 8788.0
28938016 S 8791.0
28939185 S 8788.0
28939187 S 8791.0
28941591 S 8788.0
28941592 S 8792.0
28952850 S 8788.0
28953184 B 8812.5
28953185 B 8813.5
28956124 B 8822.0
28956154 B 8819.5
28974593 S 8782.0
28976148 S 8778.0
28982578 S 8788.0
28983065 B 8816.5
28983065 B 8817.5
28990475 S 8789.0
29013204 S 8788.0
29013204 B 8790.0
29015549 B 8817.5
29019177 S 8786.0
29019435 S 8778.0
29024925 S 8780.0
29026323 B 8810.5
29045384 S 8783.0
29049454 B 8812.5
29049484 B 8811.5
29060700 B 8819.5
29062694 S 8784.0
29063604 B 8824.0
29065594 B 8827.0
29067603 S 8792.0
29067928 S 8800.0
29069573 S 8802.0
29090062 B 8829.0
29091138 S 8790.0
29109165 B 8824.5
29116414 B 8824.0
29117069 B 8816.0
29117070 B 8824.0
29226939 S 8810.0
29256301 S 8811.0
29278024 S 8810.0
29281492 S 8812.0
29293884 S 8811.0
29293884 S 8810.0
29308377 S 8813.0
29309396 S 8810.0
29309408 S 8813.0
29314590 S 8810.0
29323737 B 8822.5
29324648 B 8824.0
29337321 S 8803.0
29337368 S 8814.0
29341959 S 8818.0
29343924 S 8814.0
29346427 S 8810.0
29353141 S 8811.0
29354031 S 8810.0
29354780 S 8811.0
29356556 S 8810.0
29357468 S 8811.0
29366928 S 8810.0
29369897 S 8812.0
29371172 S 8810.0
29373350 S 8804.0
29373360 S 8809.0
29384543 S 8804.0
29384548 S 8808.0
29388641 S 8804.0
29392557 B 8823.0
29394874 S 8802.0
29394904 S 8803.0
29399803 B 8824.0
29402065 S 8804.0
29411364 S 8802.0
29411394 S 8804.0
29416894 S 8802.0
29416923 S 8803.0
29436397 S 8795.0
29437344 S 8789.0
29437374 S 8794.0
29437874 S 8789.0
29454849 S 8783.0
29454855 S 8790.0
29463988 B 8818.0
29465031 S 8796.0
29469726 B 8817.67
29471095 S 8797.0
29473515 B 8816.75
29473934 B 8817.67
29477737 B 8823.67
29492106 B 8821.67
29497034 B 8821.0
29499715 B 8814.0
29504428 S 8796.0
29504479 B 8821.67
29504480 B 8814.0
29504492 B 8821.67
29504504 B 8821.0
29504554 B 8821.67
29536772 B 8813.0
29541474 B 8810.0
29548360 B 8810.5
29553541 B 8807.7
29556917 B 8815.699999999999
29557006 S 8798.0
29567865 S 8799.0
29572151 S 8798.0
29610229 B 8819.47
29610264 B 8820.47
29624627 B 8823.67
29640243 S 8803.0
29641037 S 8805.0
29666995 B 8822.67
29667275 B 8823.67
29711906 S 8802.0
29719371 S 8808.0
29733746 B 8822.67
29733747 B 8823.67
29733781 B 8822.67
29734123 B 8823.67
29760052 S 8803.0
29760264 S 8808.0
29792133 S 8814.0
29798038 S 8808.0
29798297 S 8813.0
29800648 S 8816.0
29822073 S 8814.0
29839530 S 8810.0
29847386 B 8822.67
29864954 B 8822.0
29874343 S 8814.0
29964740 S 8810.0
30015010 B 8819.5
30024257 B 8822.0
30027876 B 8819.5
30045029 B 8822.0
30074752 B 8822.67
30074758 B 8819.0
30086992 S 8811.0
30088435 B 8822.67
30088549 S 8810.0
30154487 B 8820.17
30156052 B 8822.67
30244365 S 8810.25
30246242 S 8808.5
30246301 S 8812.0
30311623 B 8823.67
30327852 B 8824.0
30349823 B 8825.4
30359374 S 8820.0
30365915 B 8826.75
30378836 S 8812.0
30383391 B 8826.0
30384350 S 8820.0
30385435 S 8821.0
30385855 S 8820.0
30386785 B 8826.75
30386785 B 8829.0
30386785 B 8832.0
30386787 B 8829.0
30387006 B 8832.0
30387008 B 8829.0
30387287 B 8832.0
30391325 B 8848.0
30392095 B 8847.0
30395687 B 8837.0
30411438 S 8824.0
30412337 S 8820.0
30414054 S 8828.0
30419350 B 8847.0
30419385 B 8840.0
30420067 B 8847.0
30420085 B 8851.0
30420114 B 8848.0
30422845 S 8824.0
30426753 S 8820.0
30428287 B 8843.0
30431804 B 8841.0
30433666 B 8840.0
30441489 B 8841.0
30444979 B 8840.0
30450760 B 8841.0
30451439 B 8840.0
30465526 S 8834.0
30467426 B 8841.0
30484429 B 8839.0
30491597 B 8841.0
30501815 S 8821.0
30501836 S 8820.0
30501837 B 8839.0
30501866 S 8815.0
30501895 S 8818.0
30502116 B 8841.0
30509828 S 8822.0
30509978 S 8829.0
30513962 B 8844.0
30514675 S 8835.0
30514677 S 8832.0
30520807 S 8822.0
30520809 S 8829.0
30521515 S 8822.0
30525567 S 8829.0
30531906 S 8822.0
30531909 S 8829.0
30532705 S 8832.0
30541262 B 8845.0
30552477 B 8848.0
30558592 S 8834.0
30565980 S 8832.0
30568785 S 8834.0
30571226 B 8847.0
30571380 B 8846.0
30577798 B 8847.0
30578103 B 8846.0
30578244 B 8847.0
30589788 B 8845.0
30592194 S 8836.0
30597834 B 8844.0
30614305 S 8837.0
30615238 S 8836.0
30676408 S 8834.0
30677580 B 8836.0
30678270 S 8833.39
30678270 S 8832.0
30683544 S 8822.0
30684128 S 8827.0
30684846 B 8832.0
30688574 B 8836.0
30696577 S 8829.0
30718190 B 8835.0
30719580 B 8833.0
30719766 B 8835.0
30720363 B 8836.0
30724876 B 8835.0
30725246 B 8836.0
30726397 S 8827.0
30727961 S 8822.0
30735257 S 8827.0
30735813 B 8832.0
30736803 S 8822.0
30739585 B 8836.0
30741208 S 8818.0
30741608 S 8822.0
30745174 S 8818.0
30771522 S 8815.0
30773239 S 8821.0
30782070 S 8824.0
30820683 S 8821.0
30841205 S 8813.0
30843913 B 8832.0
30862962 B 8836.0
30863347 B 8832.0
30869373 S 8808.0
30869399 S 8811.0
30869416 S 8808.0
30871646 B 8836.0
30871649 B 8832.0
30871731 B 8827.0
30871732 B 8831.0
30886501 S 8811.0
30886505 S 8808.0
30886648 B 8826.0
30887906 S 8812.0
30901373 B 8831.0
30901374 B 8836.0
30901375 S 8808.0
30901377 B 8831.0
30901405 B 8836.0
30903077 S 8812.0
30907182 B 8829.0
30908512 S 8808.0
30965473 S 8812.0
30969802 B 8836.0
30974348 S 8816.0
30979158 B 8831.0
30979177 B 8836.0
30979179 B 8831.0
